<?xml version="1.0" encoding="UTF-8"?>
<!-- Generated by org.testng.reporters.JUnitXMLReporter -->
<testsuite hostname="WS0122985" name="Default test" tests="4" failures="3" timestamp="19 Nov 2014 16:21:06 GMT" time="1040.793" errors="0">
  <testcase name="do_CheckoutwithCreateAccount on [CheckoutwithCreateAccount passed=0 failed=0 skipped=0]" time="365.435" classname="test.CheckoutwithCreateAccount"/>
  <testcase name="do_CheckoutwithCreateAccount on [CheckoutwithCreateAccount passed=0 failed=0 skipped=0]" time="527.696" classname="test.CheckoutwithCreateAccount">
    <failure type="java.lang.AssertionError" message="Test case CheckoutwithCreateAccount has failed due to one of its steps not returning pass status expected [true] but found [false]">
      <![CDATA[java.lang.AssertionError: Test case CheckoutwithCreateAccount has failed due to one of its steps not returning pass status expected [true] but found [false]
	at org.testng.Assert.fail(Assert.java:94)
	at org.testng.Assert.failNotEquals(Assert.java:494)
	at org.testng.Assert.assertTrue(Assert.java:42)
	at com.hsn.util.KeywordExecutor.ExecuteKeywords(KeywordExecutor.java:152)
	at test.CheckoutwithCreateAccount.do_CheckoutwithCreateAccount(CheckoutwithCreateAccount.java:38)
	at sun.reflect.NativeMethodAccessorImpl.invoke0(Native Method)
	at sun.reflect.NativeMethodAccessorImpl.invoke(Unknown Source)
	at sun.reflect.DelegatingMethodAccessorImpl.invoke(Unknown Source)
	at java.lang.reflect.Method.invoke(Unknown Source)
	at org.testng.internal.MethodInvocationHelper.invokeMethod(MethodInvocationHelper.java:84)
	at org.testng.internal.Invoker.invokeMethod(Invoker.java:714)
	at org.testng.internal.Invoker.invokeTestMethod(Invoker.java:901)
	at org.testng.internal.Invoker.invokeTestMethods(Invoker.java:1231)
	at org.testng.internal.TestMethodWorker.invokeTestMethods(TestMethodWorker.java:127)
	at org.testng.internal.TestMethodWorker.run(TestMethodWorker.java:111)
	at org.testng.TestRunner.privateRun(TestRunner.java:767)
	at org.testng.TestRunner.run(TestRunner.java:617)
	at org.testng.SuiteRunner.runTest(SuiteRunner.java:334)
	at org.testng.SuiteRunner.runSequentially(SuiteRunner.java:329)
	at org.testng.SuiteRunner.privateRun(SuiteRunner.java:291)
	at org.testng.SuiteRunner.run(SuiteRunner.java:240)
	at org.testng.SuiteRunnerWorker.runSuite(SuiteRunnerWorker.java:52)
	at org.testng.SuiteRunnerWorker.run(SuiteRunnerWorker.java:86)
	at org.testng.TestNG.runSuitesSequentially(TestNG.java:1224)
	at org.testng.TestNG.runSuitesLocally(TestNG.java:1149)
	at org.testng.TestNG.run(TestNG.java:1057)
	at org.testng.remote.RemoteTestNG.run(RemoteTestNG.java:111)
	at org.testng.remote.RemoteTestNG.initAndRun(RemoteTestNG.java:204)
	at org.testng.remote.RemoteTestNG.main(RemoteTestNG.java:175)
]]>
    </failure>
  </testcase> <!-- do_CheckoutwithCreateAccount on [CheckoutwithCreateAccount passed=0 failed=0 skipped=0] -->
  <testcase name="do_CheckoutwithCreateAccount on [CheckoutwithCreateAccount passed=0 failed=0 skipped=0]" time="66.695" classname="test.CheckoutwithCreateAccount">
    <failure type="java.lang.reflect.InvocationTargetException">
      <![CDATA[java.lang.reflect.InvocationTargetException
	at sun.reflect.NativeMethodAccessorImpl.invoke0(Native Method)
	at sun.reflect.NativeMethodAccessorImpl.invoke(Unknown Source)
	at sun.reflect.DelegatingMethodAccessorImpl.invoke(Unknown Source)
	at java.lang.reflect.Method.invoke(Unknown Source)
	at com.hsn.util.KeywordExecutor.ExecuteKeywords(KeywordExecutor.java:116)
	at test.CheckoutwithCreateAccount.do_CheckoutwithCreateAccount(CheckoutwithCreateAccount.java:38)
	at sun.reflect.NativeMethodAccessorImpl.invoke0(Native Method)
	at sun.reflect.NativeMethodAccessorImpl.invoke(Unknown Source)
	at sun.reflect.DelegatingMethodAccessorImpl.invoke(Unknown Source)
	at java.lang.reflect.Method.invoke(Unknown Source)
	at org.testng.internal.MethodInvocationHelper.invokeMethod(MethodInvocationHelper.java:84)
	at org.testng.internal.Invoker.invokeMethod(Invoker.java:714)
	at org.testng.internal.Invoker.invokeTestMethod(Invoker.java:901)
	at org.testng.internal.Invoker.invokeTestMethods(Invoker.java:1231)
	at org.testng.internal.TestMethodWorker.invokeTestMethods(TestMethodWorker.java:127)
	at org.testng.internal.TestMethodWorker.run(TestMethodWorker.java:111)
	at org.testng.TestRunner.privateRun(TestRunner.java:767)
	at org.testng.TestRunner.run(TestRunner.java:617)
	at org.testng.SuiteRunner.runTest(SuiteRunner.java:334)
	at org.testng.SuiteRunner.runSequentially(SuiteRunner.java:329)
	at org.testng.SuiteRunner.privateRun(SuiteRunner.java:291)
	at org.testng.SuiteRunner.run(SuiteRunner.java:240)
	at org.testng.SuiteRunnerWorker.runSuite(SuiteRunnerWorker.java:52)
	at org.testng.SuiteRunnerWorker.run(SuiteRunnerWorker.java:86)
	at org.testng.TestNG.runSuitesSequentially(TestNG.java:1224)
	at org.testng.TestNG.runSuitesLocally(TestNG.java:1149)
	at org.testng.TestNG.run(TestNG.java:1057)
	at org.testng.remote.RemoteTestNG.run(RemoteTestNG.java:111)
	at org.testng.remote.RemoteTestNG.initAndRun(RemoteTestNG.java:204)
	at org.testng.remote.RemoteTestNG.main(RemoteTestNG.java:175)
Caused by: org.openqa.selenium.remote.SessionNotFoundException: The FirefoxDriver cannot be used after quit() was called.
Build info: version: '2.43.0', revision: '597b76b', time: '2014-09-09 20:52:14'
System info: host: 'WS0122985', ip: '10.17.225.21', os.name: 'Windows 7', os.arch: 'amd64', os.version: '6.1', java.version: '1.7.0_13'
Driver info: driver.version: FirefoxDriver
	at org.openqa.selenium.firefox.FirefoxDriver$LazyCommandExecutor.execute(FirefoxDriver.java:361)
	at org.openqa.selenium.remote.RemoteWebDriver.execute(RemoteWebDriver.java:572)
	at org.openqa.selenium.firefox.FirefoxDriver.access$0(FirefoxDriver.java:1)
	at org.openqa.selenium.firefox.FirefoxDriver$1$1.implicitlyWait(FirefoxDriver.java:219)
	at com.hsn.util.Keywords.closeModalsFast(Keywords.java:591)
	at com.hsn.util.Keywords.addProductToBag(Keywords.java:2751)
	... 30 more
]]>
    </failure>
  </testcase> <!-- do_CheckoutwithCreateAccount on [CheckoutwithCreateAccount passed=0 failed=0 skipped=0] -->
  <testcase name="do_CheckoutwithCreateAccount on [CheckoutwithCreateAccount passed=0 failed=0 skipped=0]" time="79.462" classname="test.CheckoutwithCreateAccount">
    <failure type="java.lang.reflect.InvocationTargetException">
      <![CDATA[java.lang.reflect.InvocationTargetException
	at sun.reflect.NativeMethodAccessorImpl.invoke0(Native Method)
	at sun.reflect.NativeMethodAccessorImpl.invoke(Unknown Source)
	at sun.reflect.DelegatingMethodAccessorImpl.invoke(Unknown Source)
	at java.lang.reflect.Method.invoke(Unknown Source)
	at com.hsn.util.KeywordExecutor.ExecuteKeywords(KeywordExecutor.java:116)
	at test.CheckoutwithCreateAccount.do_CheckoutwithCreateAccount(CheckoutwithCreateAccount.java:38)
	at sun.reflect.NativeMethodAccessorImpl.invoke0(Native Method)
	at sun.reflect.NativeMethodAccessorImpl.invoke(Unknown Source)
	at sun.reflect.DelegatingMethodAccessorImpl.invoke(Unknown Source)
	at java.lang.reflect.Method.invoke(Unknown Source)
	at org.testng.internal.MethodInvocationHelper.invokeMethod(MethodInvocationHelper.java:84)
	at org.testng.internal.Invoker.invokeMethod(Invoker.java:714)
	at org.testng.internal.Invoker.invokeTestMethod(Invoker.java:901)
	at org.testng.internal.Invoker.invokeTestMethods(Invoker.java:1231)
	at org.testng.internal.TestMethodWorker.invokeTestMethods(TestMethodWorker.java:127)
	at org.testng.internal.TestMethodWorker.run(TestMethodWorker.java:111)
	at org.testng.TestRunner.privateRun(TestRunner.java:767)
	at org.testng.TestRunner.run(TestRunner.java:617)
	at org.testng.SuiteRunner.runTest(SuiteRunner.java:334)
	at org.testng.SuiteRunner.runSequentially(SuiteRunner.java:329)
	at org.testng.SuiteRunner.privateRun(SuiteRunner.java:291)
	at org.testng.SuiteRunner.run(SuiteRunner.java:240)
	at org.testng.SuiteRunnerWorker.runSuite(SuiteRunnerWorker.java:52)
	at org.testng.SuiteRunnerWorker.run(SuiteRunnerWorker.java:86)
	at org.testng.TestNG.runSuitesSequentially(TestNG.java:1224)
	at org.testng.TestNG.runSuitesLocally(TestNG.java:1149)
	at org.testng.TestNG.run(TestNG.java:1057)
	at org.testng.remote.RemoteTestNG.run(RemoteTestNG.java:111)
	at org.testng.remote.RemoteTestNG.initAndRun(RemoteTestNG.java:204)
	at org.testng.remote.RemoteTestNG.main(RemoteTestNG.java:175)
Caused by: org.openqa.selenium.remote.SessionNotFoundException: The FirefoxDriver cannot be used after quit() was called.
Build info: version: '2.43.0', revision: '597b76b', time: '2014-09-09 20:52:14'
System info: host: 'WS0122985', ip: '10.17.225.21', os.name: 'Windows 7', os.arch: 'amd64', os.version: '6.1', java.version: '1.7.0_13'
Driver info: driver.version: FirefoxDriver
	at org.openqa.selenium.firefox.FirefoxDriver$LazyCommandExecutor.execute(FirefoxDriver.java:361)
	at org.openqa.selenium.remote.RemoteWebDriver.execute(RemoteWebDriver.java:572)
	at org.openqa.selenium.firefox.FirefoxDriver.access$0(FirefoxDriver.java:1)
	at org.openqa.selenium.firefox.FirefoxDriver$1$1.implicitlyWait(FirefoxDriver.java:219)
	at com.hsn.util.Keywords.closeModals(Keywords.java:564)
	at com.hsn.util.Keywords.click(Keywords.java:691)
	... 30 more
]]>
    </failure>
  </testcase> <!-- do_CheckoutwithCreateAccount on [CheckoutwithCreateAccount passed=0 failed=0 skipped=0] -->
</testsuite> <!-- Default test -->
